Workbook

Sheet Parameters
A1: Simulation Name | B1: Simulation Name | C1: Test unlimited | D1: Test unlimited | E1: Test unlimited | F1: Test unlimited | G1: Test unlimited | H1: Test unlimited | I1: Test unlimited | J1: Test unlimited | K1: Test unlimited
A2: Simulation Comment | B2: Simulation Comment
A3: BridgeCare Rules Creator: | B3: Central Office | J3: Simulation Last Run: | K3: 1/15/2026
A4: BridgeCare Rules Date: | B4: 1/15/2026
A6: Network Name | B6: Network Name
A7: Network: | B7: 2024 Q2 Base Data
A9: Parameters are based on the criteria editor inputs
A10: NHS | B10: NHS | F10: Investment: | G10: Investment: | H10: Investment: | L10: Analysis: | M10: Analysis: | N10: Analysis: | O10: Analysis:
A11: NHS | B11: N
A12: Non-NHS | B12: Y | F12: Start Year: | G12: Start Year: | H12: 2026 | L12: Optimization: | M12: Optimization: | N12: BenefitToCostRatio | O12: BenefitToCostRatio
A14: 6A19 BPN | B14: 6A19 BPN | F14: Analysis Period: | G14: Analysis Period: | H14: 11 | L14: Budget: | M14: Budget: | N14: UnlimitedSpending | O14: UnlimitedSpending
A15: 1 | B15: N
A16: 2 | B16: N | F16: Inflation Rate: | G16: Inflation Rate: | H16: 3 | L16: Weighting: | M16: Weighting: | N16: RISK_SCORE | O16: RISK_SCORE
A17: 3 | B17: N
A18: 4 | B18: N | D18: 5A21 Owner | E18: 5A21 Owner | F18: 5A21 Owner | H18: 5C22 Functional Class | I18: 5C22 Functional Class | J18: 5C22 Functional Class | L18: Benefit: | M18: Benefit: | N18: CONDITIONINDEX | O18: CONDITIONINDEX
A19: H | B19: N | D19: 01 - State Highway Agency | E19: 01 - State Highway Agency | F19: N | H19: Rural | I19: Rural | J19: Rural
A20: L | B20: Y | D20: 02 - County Highway Agency | E20: 02 - County Highway Agency | F20: Y | H20: 01 - Rural - Principal Arterial - Interstate | I20: 01 - Rural - Principal Arterial - Interstate | J20: N | L20: Jurisdiction Criteria: | M20: Jurisdiction Criteria: | N20: ([DISTRICT]='04' AND [INTERNET_REPORT]='Local' AND [COUNTY]='Pike' AND [NBISLEN]='Y' AND ([CULV_SEEDED]<'5' OR [DECK_SEEDED]<'5' OR [SUB_SEEDED]<'5' OR [SUP_SEEDED]<'5')) | O20: ([DISTRICT]='04' AND [INTERNET_REPORT]='Local' AND [COUNTY]='Pike' AND [NBISLEN]='Y' AND ([CULV_SEEDED]<'5' OR [DECK_SEEDED]<'5' OR [SUB_SEEDED]<'5' OR [SUP_SEEDED]<'5')) | P20: ([DISTRICT]='04' AND [INTERNET_REPORT]='Local' AND [COUNTY]='Pike' AND [NBISLEN]='Y' AND ([CULV_SEEDED]<'5' OR [DECK_SEEDED]<'5' OR [SUB_SEEDED]<'5' OR [SUP_SEEDED]<'5')) | Q20: ([DISTRICT]='04' AND [INTERNET_REPORT]='Local' AND [COUNTY]='Pike' AND [NBISLEN]='Y' AND ([CULV_SEEDED]<'5' OR [DECK_SEEDED]<'5' OR [SUB_SEEDED]<'5' OR [SUP_SEEDED]<'5')) | R20: ([DISTRICT]='04' AND [INTERNET_REPORT]='Local' AND [COUNTY]='Pike' AND [NBISLEN]='Y' AND ([CULV_SEEDED]<'5' OR [DECK_SEEDED]<'5' OR [SUB_SEEDED]<'5' OR [SUP_SEEDED]<'5')) | S20: ([DISTRICT]='04' AND [INTERNET_REPORT]='Local' AND [COUNTY]='Pike' AND [NBISLEN]='Y' AND ([CULV_SEEDED]<'5' OR [DECK_SEEDED]<'5' OR [SUB_SEEDED]<'5' OR [SUP_SEEDED]<'5')) | T20: ([DISTRICT]='04' AND [INTERNET_REPORT]='Local' AND [COUNTY]='Pike' AND [NBISLEN]='Y' AND ([CULV_SEEDED]<'5' OR [DECK_SEEDED]<'5' OR [SUB_SEEDED]<'5' OR [SUP_SEEDED]<'5')) | U20: ([DISTRICT]='04' AND [INTERNET_REPORT]='Local' AND [COUNTY]='Pike' AND [NBISLEN]='Y' AND ([CULV_SEEDED]<'5' OR [DECK_SEEDED]<'5' OR [SUB_SEEDED]<'5' OR [SUP_SEEDED]<'5')) | V20: ([DISTRICT]='04' AND [INTERNET_REPORT]='Local' AND [COUNTY]='Pike' AND [NBISLEN]='Y' AND ([CULV_SEEDED]<'5' OR [DECK_SEEDED]<'5' OR [SUB_SEEDED]<'5' OR [SUP_SEEDED]<'5')) | W20: ([DISTRICT]='04' AND [INTERNET_REPORT]='Local' AND [COUNTY]='Pike' AND [NBISLEN]='Y' AND ([CULV_SEEDED]<'5' OR [DECK_SEEDED]<'5' OR [SUB_SEEDED]<'5' OR [SUP_SEEDED]<'5')) | X20: ([DISTRICT]='04' AND [INTERNET_REPORT]='Local' AND [COUNTY]='Pike' AND [NBISLEN]='Y' AND ([CULV_SEEDED]<'5' OR [DECK_SEEDED]<'5' OR [SUB_SEEDED]<'5' OR [SUP_SEEDED]<'5')) | Y20: ([DISTRICT]='04' AND [INTERNET_REPORT]='Local' AND [COUNTY]='Pike' AND [NBISLEN]='Y' AND ([CULV_SEEDED]<'5' OR [DECK_SEEDED]<'5' OR [SUB_SEEDED]<'5' OR [SUP_SEEDED]<'5')) | Z20: ([DISTRICT]='04' AND [INTERNET_REPORT]='Local' AND [COUNTY]='Pike' AND [NBISLEN]='Y' AND ([CULV_SEEDED]<'5' OR [DECK_SEEDED]<'5' OR [SUB_SEEDED]<'5' OR [SUP_SEEDED]<'5'))
A21: T | B21: N | D21: 03 - Town or Township Highway Agency | E21: 03 - Town or Township Highway Agency | F21: Y | H21: 02 - Rural - Principal Arterial - Other | I21: 02 - Rural - Principal Arterial - Other | J21: N
A22: D | B22: N | D22: 04 - City, Municipal Highway Agency or Borough | E22: 04 - City, Municipal Highway Agency or Borough | F22: N | H22: 03 - Rural - Other Freeway/Expressway | I22: 03 - Rural - Other Freeway/Expressway | J22: N
A23: N | B23: N | D23: 11 - State Park, Forest or Reservation Agency | E23: 11 - State Park, Forest or Reservation Agency | F23: N | H23: 06 - Rural - Minor Arterial | I23: 06 - Rural - Minor Arterial | J23: N | L23: Number | M23: Criteria: | N23: Analysis Priorites: | O23: Analysis Priorites: | P23: Analysis Priorites: | Q23: Analysis Priorites: | R23: Analysis Priorites: | S23: Analysis Priorites: | T23: Analysis Priorites: | U23: Analysis Priorites: | V23: Analysis Priorites: | W23: Analysis Priorites: | X23: Analysis Priorites: | Y23: Analysis Priorites: | Z23: Analysis Priorites:
A24: Blank | B24: N | D24: 12 - Local Park, Forest or Reservation Agency | E24: 12 - Local Park, Forest or Reservation Agency | F24: N | H24: 07 - Rural - Major Collector | I24: 07 - Rural - Major Collector | J24: N
D25: 21 - Other State Agency | E25: 21 - Other State Agency | F25: N | H25: 08 - Rural - Minor Collector | I25: 08 - Rural - Minor Collector | J25: N | L25: 1 | M25: (([BRIDGE_TYPE]='B' AND ([DECK_SEEDED]<='3.5' OR [SUP_SEEDED]<='3.5' OR [SUB_SEEDED]<='3.5')) OR ([BRIDGE_TYPE]='C' AND [CULV_SEEDED]<='3.5')) AND ([NHS_IND]='1' OR ([NHS_IND]='0' AND [RISK_SCORE]>='15000'))
D26: 25 - Other local Agency | E26: 25 - Other local Agency | F26: N | H26: 09 - Rural - Local | I26: 09 - Rural - Local | J26: Y | L26: 2 | M26: ([POST_STATUS]<>'CLOSED' AND ([DECK_SEEDED]<'3.0' OR [SUP_SEEDED]<'3.0' OR [SUB_SEEDED]<'3.0'))
A27: Bridge Length | B27: Bridge Length | D27: 26 - Private (Other than Railroad) | E27: 26 - Private (Other than Railroad) | F27: N | H27: NN - Other | I27: NN - Other | J27: N | L27: 3 | M27: [BRIDGE_TYPE]='C' OR [BRIDGE_TYPE]='B'
A28: 8-20 | B28: N | D28: 27 - Railroad | E28: 27 - Railroad | F28: N | H28: Urban | I28: Urban | J28: Urban
A29: NBIS Length | B29: Y | D29: 31 - State Toll Authority | E29: 31 - State Toll Authority | F29: N | H29: 11 - Urban - Principal Arterial - Interstate | I29: 11 - Urban - Principal Arterial - Interstate | J29: N | L29: Budget Split Criteria
D30: 32 - Local Toll Authority | E30: 32 - Local Toll Authority | F30: N | H30: 12 - Urban - Principal Arterial - Other Freeway & Expressways | I30: 12 - Urban - Principal Arterial - Other Freeway & Expressways | J30: N | L30: Rank | M30: Amount | N30: Percentage
A31: Status | B31: Status | D31: 60 - Other Federal Agencies | E31: 60 - Other Federal Agencies | F31: N | H31: 14 - Urban - Other Principal Arterial | I31: 14 - Urban - Other Principal Arterial | J31: N | L31: 1 | M31: 5000000 | N31: 100
A32: Open | B32: Y | D32: 62 - Bureau of Indian Affairs | E32: 62 - Bureau of Indian Affairs | F32: N | H32: 16 - Urban - Minor Arterial | I32: 16 - Urban - Minor Arterial | J32: N | L32: 2 | M32: 30000000 | N32: 50/50
A33: Closed | B33: N | D33: 64 - U.S. Forest Service | E33: 64 - U.S. Forest Service | F33: N | H33: 17 - Urban - Collector | I33: 17 - Urban - Collector | J33: N | L33: 3 | M33: 50000000 | N33: 33/33/34
A34: P3 | B34: N | D34: 66 - National Park Service | E34: 66 - National Park Service | F34: N | H34: 19 - Urban - Local | I34: 19 - Urban - Local | J34: N | L34: 4 | M34: 100000000 | N34: 25/25/25/25
A35: Posted | B35: Y | D35: 68 - Bureau of Land Management | E35: 68 - Bureau of Land Management | F35: N | H35: NN - Other | I35: NN - Other | J35: N | L35: 5 | M35: 100000001 | N35: 20/20/20/20/20
D36: 69 - Bureau of Reclamation | E36: 69 - Bureau of Reclamation | F36: N | H36: 99 - Urban - Ramp | I36: 99 - Urban - Ramp | J36: N
A37: Treatments in Simulations | B37: Treatments in Simulations | D37: 70 - Military Reservation Corps Engineers | E37: 70 - Military Reservation Corps Engineers | F37: N
A38: BAMS | B38: MPMS | D38: 80 - Unknown | E38: 80 - Unknown | F38: N
A39: Bituminous Overlay | D39: XX - Demolished/Replaced | E39: XX - Demolished/Replaced | F39: N
A40: Bridge Replacement
A41: Culvert Rehab (Other)
A42: Culvert Replacement (Box Frame
A43: Culvert Replacement (Other)
...

Sheet Legend
A1: Color Key | B1: Color Key | I1: Tab Definitions
E2: Posted / Closed Bridge Condition Range | F2: Posted / Closed Bridge Condition Range | G2: Posted / Closed Bridge Condition Range | I2: Parameters: Summary of simulation data inputs.
A3: Work Done Columns | B3: Work Done Columns | E3: Posted / Closed Bridge Condition Range | F3: Posted / Closed Bridge Condition Range | G3: Posted / Closed Bridge Condition Range | I3: Bridge Data: Complete recommended treatments for all structures throughout the analysis period
A4: Bridge project is being cashed flowed. | B4: Bridge project is being cashed flowed. | E4: Posted Condition < | F4: Posted Condition < | G4: 4.1 | I4: Funded Treatment List: Provides a list of funded treatments for the analysis period
A5: MPMS Project is being Cash Flowed. | B5: MPMS Project is being Cash Flowed. | E5: Closed Condition < | F5: Closed Condition < | G5: 3 | I5: Unfunded Treatment — Final List: First year of unfunded treatments by BRKEY.
I6: Unfunded Treatment — Time: List of unfunded treatments through time.
A7: Details Columns | B7: Details Columns | I7: Bridge Work Summary: Summary of projected costs for treatments throughout simulation period for all structures. Summary of projected condition changes throughout analysis period.
A8: Bridge project is being cashed flowed. | B8: Bridge project is being cashed flowed. | E8: Condition Limits | F8: Condition Limits | G8: Condition Limits | I8: Bridge Work Summary by Budget: Summary of projected costs for treatments throughout simulation period for all bridges by specific budget.
A9: MPMS Project is being Cash Flowed. | B9: MPMS Project is being Cash Flowed. | E9: Good Min Cond > | F9: Good Min Cond > | G9: 7 | I9: District Totals: Projected spending per district each year throughout analysis period.
A10: Min Condition is less than or equal to 3.5 | B10: Min Condition is less than or equal to 3.5 | E10: Poor Min Cond < | F10: Poor Min Cond < | G10: 5 | I10: NHS Count: Graph of projected bridge conditions for structures on the NHS by bridge count.
I11: NHS DA: Graph of projected bridge conditions for structures on the NHS by deck area.
I12: Non-NHS Count: Graph of projected bridge conditions for structures not on the NHS by bridge count.
A13: example: | I13: Non-NHS DA: Graph of projected bridge conditions for structures not on the NHS by deck area.
I14: Combined Count: Graph of projected bridge conditions for all structures by bridge count.
A15: 2021 | B15: 2022 | C15: 2023 | I15: Combined DA: Graph of projected bridge conditions for all structures by deck area.
A16: Brdg_Repl | B16: Brdg_Repl | C16: Brdg_Repl | I16: Poor Count: Graph showing projected number of structures to be in poor condition throughout analysis period.
A17: Bridge replacement is cash flowed over 3 years. | I17: Poor DA: Graph showing projected deck area of structures to be in poor condition throughout analysis period.
I18: Poor DA by BPN: Graph showing projected deck area of structures to be in poor condition, by BPN, throughout analysis period.
I19: Posted BPN Count: Graph showing projected number of structures to be posted based on the GCR Super and not by load capacity calculations. Since it is not possible to perform load calculations at this level, this can be considered a proxy and should be used only for only long-term evaluation.
I20: Posted BPN DA: Graph showing projected deck area of structures to be posted based on the GCR Super and not by load capacity calculations. Since it is not possible to perform load calculations at this level, this can be considered a proxy and should be used only for long-term evaluation.
I21: Closed BPN Count: Graph showing the projected number of structures to be closed based on the min GCR. In order to be considered closed the Min GCR value must be less than 3
I22: Closed BPN DA: Graph showing projected deck area to be closed based on the min GCR. In order to be considered closed the Min GCR value must be less than 3
I23: Combined Posted and Closed: Graph showing the combined number of structures that are projected to be closed and posted
I24: $ Needed DA BPN: Graph showing the amount of money spent by BPN
A26: • For individual bridge column definitions, please see Pub 100A | B26: • For individual bridge column definitions, please see Pub 100A | C26: • For individual bridge column definitions, please see Pub 100A | D26: • For individual bridge column definitions, please see Pub 100A | E26: • For individual bridge column definitions, please see Pub 100A | F26: • For individual bridge column definitions, please see Pub 100A | G26: • For individual bridge column definitions, please see Pub 100A | H26: • For individual bridge column definitions, please see Pub 100A
A27: • For other publications please see below, | B27: • For other publications please see below, | C27: • For other publications please see below, | D27: • For other publications please see below, | E27: • For other publications please see below, | F27: • For other publications please see below, | G27: • For other publications please see below, | H27: • For other publications please see below,
A28: ==HYPERLINK("https://docs.penndot.pa.gov/Public/Bureaus/BOO/AMPortal/", "PennDOT-Asset Management Portal") | B28: ==HYPERLINK("https://docs.penndot.pa.gov/Public/Bureaus/BOO/AMPortal/", "PennDOT-Asset Management Portal") | C28: ==HYPERLINK("https://docs.penndot.pa.gov/Public/Bureaus/BOO/AMPortal/", "PennDOT-Asset Management Portal") | D28: ==HYPERLINK("https://docs.penndot.pa.gov/Public/Bureaus/BOO/AMPortal/", "PennDOT-Asset Management Portal") | E28: ==HYPERLINK("https://docs.penndot.pa.gov/Public/Bureaus/BOO/AMPortal/", "PennDOT-Asset Management Portal") | F28: ==HYPERLINK("https://docs.penndot.pa.gov/Public/Bureaus/BOO/AMPortal/", "PennDOT-Asset Management Portal") | G28: ==HYPERLINK("https://docs.penndot.pa.gov/Public/Bureaus/BOO/AMPortal/", "PennDOT-Asset Management Portal") | H28: ==HYPERLINK("https://docs.penndot.pa.gov/Public/Bureaus/BOO/AMPortal/", "PennDOT-Asset Management Portal")
A29: This software is provided on “as is” basis, and by using the software you acknowledge and agree that you are doing so at your own risk. While reasonable efforts have been made to ensure the accuracy and reliability of the software, no guarantee is made regarding the correctness, completeness, or suitability of any models, predictions or results it generates. Under no circumstances shall the software developers or distributors be held liable for any loss, damage, or other consequences arising from the use of the software or its outputs. Users assume full responsibility for any decisions made based on software use. | B29: This software is provided on “as is” basis, and by using the software you acknowledge and agree that you are doing so at your own risk. While reasonable efforts have been made to ensure the accuracy and reliability of the software, no guarantee is made regarding the correctness, completeness, or suitability of any models, predictions or results it generates. Under no circumstances shall the software developers or distributors be held liable for any loss, damage, or other consequences arising from the use of the software or its outputs. Users assume full responsibility for any decisions made based on software use. | C29: This software is provided on “as is” basis, and by using the software you acknowledge and agree that you are doing so at your own risk. While reasonable efforts have been made to ensure the accuracy and reliability of the software, no guarantee is made regarding the correctness, completeness, or suitability of any models, predictions or results it generates. Under no circumstances shall the software developers or distributors be held liable for any loss, damage, or other consequences arising from the use of the software or its outputs. Users assume full responsibility for any decisions made based on software use. | D29: This software is provided on “as is” basis, and by using the software you acknowledge and agree that you are doing so at your own risk. While reasonable efforts have been made to ensure the accuracy and reliability of the software, no guarantee is made regarding the correctness, completeness, or suitability of any models, predictions or results it generates. Under no circumstances shall the software developers or distributors be held liable for any loss, damage, or other consequences arising from the use of the software or its outputs. Users assume full responsibility for any decisions made based on software use. | E29: This software is provided on “as is” basis, and by using the software you acknowledge and agree that you are doing so at your own risk. While reasonable efforts have been made to ensure the accuracy and reliability of the software, no guarantee is made regarding the correctness, completeness, or suitability of any models, predictions or results it generates. Under no circumstances shall the software developers or distributors be held liable for any loss, damage, or other consequences arising from the use of the software or its outputs. Users assume full responsibility for any decisions made based on software use. | F29: This software is provided on “as is” basis, and by using the software you acknowledge and agree that you are doing so at your own risk. While reasonable efforts have been made to ensure the accuracy and reliability of the software, no guarantee is made regarding the correctness, completeness, or suitability of any models, predictions or results it generates. Under no circumstances shall the software developers or distributors be held liable for any loss, damage, or other consequences arising from the use of the software or its outputs. Users assume full responsibility for any decisions made based on software use. | G29: This software is provided on “as is” basis, and by using the software you acknowledge and agree that you are doing so at your own risk. While reasonable efforts have been made to ensure the accuracy and reliability of the software, no guarantee is made regarding the correctness, completeness, or suitability of any models, predictions or results it generates. Under no circumstances shall the software developers or distributors be held liable for any loss, damage, or other consequences arising from the use of the software or its outputs. Users assume full responsibility for any decisions made based on software use. | H29: This software is provided on “as is” basis, and by using the software you acknowledge and agree that you are doing so at your own risk. While reasonable efforts have been made to ensure the accuracy and reliability of the software, no guarantee is made regarding the correctness, completeness, or suitability of any models, predictions or results it generates. Under no circumstances shall the software developers or distributors be held liable for any loss, damage, or other consequences arising from the use of the software or its outputs. Users assume full responsibility for any decisions made based on software use.
A30: This software is provided on “as is” basis, and by using the software you acknowledge and agree that you are doing so at your own risk. While reasonable efforts have been made to ensure the accuracy and reliability of the software, no guarantee is made regarding the correctness, completeness, or suitability of any models, predictions or results it generates. Under no circumstances shall the software developers or distributors be held liable for any loss, damage, or other consequences arising from the use of the software or its outputs. Users assume full responsibility for any decisions made based on software use. | B30: This software is provided on “as is” basis, and by using the software you acknowledge and agree that you are doing so at your own risk. While reasonable efforts have been made to ensure the accuracy and reliability of the software, no guarantee is made regarding the correctness, completeness, or suitability of any models, predictions or results it generates. Under no circumstances shall the software developers or distributors be held liable for any loss, damage, or other consequences arising from the use of the software or its outputs. Users assume full responsibility for any decisions made based on software use. | C30: This software is provided on “as is” basis, and by using the software you acknowledge and agree that you are doing so at your own risk. While reasonable efforts have been made to ensure the accuracy and reliability of the software, no guarantee is made regarding the correctness, completeness, or suitability of any models, predictions or results it generates. Under no circumstances shall the software developers or distributors be held liable for any loss, damage, or other consequences arising from the use of the software or its outputs. Users assume full responsibility for any decisions made based on software use. | D30: This software is provided on “as is” basis, and by using the software you acknowledge and agree that you are doing so at your own risk. While reasonable efforts have been made to ensure the accuracy and reliability of the software, no guarantee is made regarding the correctness, completeness, or suitability of any models, predictions or results it generates. Under no circumstances shall the software developers or distributors be held liable for any loss, damage, or other consequences arising from the use of the software or its outputs. Users assume full responsibility for any decisions made based on software use. | E30: This software is provided on “as is” basis, and by using the software you acknowledge and agree that you are doing so at your own risk. While reasonable efforts have been made to ensure the accuracy and reliability of the software, no guarantee is made regarding the correctness, completeness, or suitability of any models, predictions or results it generates. Under no circumstances shall the software developers or distributors be held liable for any loss, damage, or other consequences arising from the use of the software or its outputs. Users assume full responsibility for any decisions made based on software use. | F30: This software is provided on “as is” basis, and by using the software you acknowledge and agree that you are doing so at your own risk. While reasonable efforts have been made to ensure the accuracy and reliability of the software, no guarantee is made regarding the correctness, completeness, or suitability of any models, predictions or results it generates. Under no circumstances shall the software developers or distributors be held liable for any loss, damage, or other consequences arising from the use of the software or its outputs. Users assume full responsibility for any decisions made based on software use. | G30: This software is provided on “as is” basis, and by using the software you acknowledge and agree that you are doing so at your own risk. While reasonable efforts have been made to ensure the accuracy and reliability of the software, no guarantee is made regarding the correctness, completeness, or suitability of any models, predictions or results it generates. Under no circumstances shall the software developers or distributors be held liable for any loss, damage, or other consequences arising from the use of the software or its outputs. Users assume full responsibility for any decisions made based on software use. | H30: This software is provided on “as is” basis, and by using the software you acknowledge and agree that you are doing so at your own risk. While reasonable efforts have been made to ensure the accuracy and reliability of the software, no guarantee is made regarding the correctness, completeness, or suitability of any models, predictions or results it generates. Under no circumstances shall the software developers or distributors be held liable for any loss, damage, or other consequences arising from the use of the software or its outputs. Users assume full responsibility for any decisions made based on software use.
A31: This software is provided on “as is” basis, and by using the software you acknowledge and agree that you are doing so at your own risk. While reasonable efforts have been made to ensure the accuracy and reliability of the software, no guarantee is made regarding the correctness, completeness, or suitability of any models, predictions or results it generates. Under no circumstances shall the software developers or distributors be held liable for any loss, damage, or other consequences arising from the use of the software or its outputs. Users assume full responsibility for any decisions made based on software use. | B31: This software is provided on “as is” basis, and by using the software you acknowledge and agree that you are doing so at your own risk. While reasonable efforts have been made to ensure the accuracy and reliability of the software, no guarantee is made regarding the correctness, completeness, or suitability of any models, predictions or results it generates. Under no circumstances shall the software developers or distributors be held liable for any loss, damage, or other consequences arising from the use of the software or its outputs. Users assume full responsibility for any decisions made based on software use. | C31: This software is provided on “as is” basis, and by using the software you acknowledge and agree that you are doing so at your own risk. While reasonable efforts have been made to ensure the accuracy and reliability of the software, no guarantee is made regarding the correctness, completeness, or suitability of any models, predictions or results it generates. Under no circumstances shall the software developers or distributors be held liable for any loss, damage, or other consequences arising from the use of the software or its outputs. Users assume full responsibility for any decisions made based on software use. | D31: This software is provided on “as is” basis, and by using the software you acknowledge and agree that you are doing so at your own risk. While reasonable efforts have been made to ensure the accuracy and reliability of the software, no guarantee is made regarding the correctness, completeness, or suitability of any models, predictions or results it generates. Under no circumstances shall the software developers or distributors be held liable for any loss, damage, or other consequences arising from the use of the software or its outputs. Users assume full responsibility for any decisions made based on software use. | E31: This software is provided on “as is” basis, and by using the software you acknowledge and agree that you are doing so at your own risk. While reasonable efforts have been made to ensure the accuracy and reliability of the software, no guarantee is made regarding the correctness, completeness, or suitability of any models, predictions or results it generates. Under no circumstances shall the software developers or distributors be held liable for any loss, damage, or other consequences arising from the use of the software or its outputs. Users assume full responsibility for any decisions made based on software use. | F31: This software is provided on “as is” basis, and by using the software you acknowledge and agree that you are doing so at your own risk. While reasonable efforts have been made to ensure the accuracy and reliability of the software, no guarantee is made regarding the correctness, completeness, or suitability of any models, predictions or results it generates. Under no circumstances shall the software developers or distributors be held liable for any loss, damage, or other consequences arising from the use of the software or its outputs. Users assume full responsibility for any decisions made based on software use. | G31: This software is provided on “as is” basis, and by using the software you acknowledge and agree that you are doing so at your own risk. While reasonable efforts have been made to ensure the accuracy and reliability of the software, no guarantee is made regarding the correctness, completeness, or suitability of any models, predictions or results it generates. Under no circumstances shall the software developers or distributors be held liable for any loss, damage, or other consequences arising from the use of the software or its outputs. Users assume full responsibility for any decisions made based on software use. | H31: This software is provided on “as is” basis, and by using the software you acknowledge and agree that you are doing so at your own risk. While reasonable efforts have been made to ensure the accuracy and reliability of the software, no guarantee is made regarding the correctness, completeness, or suitability of any models, predictions or results it generates. Under no circumstances shall the software developers or distributors be held liable for any loss, damage, or other consequences arising from the use of the software or its outputs. Users assume full responsibility for any decisions made based on software use.
A32: This software is provided on “as is” basis, and by using the software you acknowledge and agree that you are doing so at your own risk. While reasonable efforts have been made to ensure the accuracy and reliability of the software, no guarantee is made regarding the correctness, completeness, or suitability of any models, predictions or results it generates. Under no circumstances shall the software developers or distributors be held liable for any loss, damage, or other consequences arising from the use of the software or its outputs. Users assume full responsibility for any decisions made based on software use. | B32: This software is provided on “as is” basis, and by using the software you acknowledge and agree that you are doing so at your own risk. While reasonable efforts have been made to ensure the accuracy and reliability of the software, no guarantee is made regarding the correctness, completeness, or suitability of any models, predictions or results it generates. Under no circumstances shall the software developers or distributors be held liable for any loss, damage, or other consequences arising from the use of the software or its outputs. Users assume full responsibility for any decisions made based on software use. | C32: This software is provided on “as is” basis, and by using the software you acknowledge and agree that you are doing so at your own risk. While reasonable efforts have been made to ensure the accuracy and reliability of the software, no guarantee is made regarding the correctness, completeness, or suitability of any models, predictions or results it generates. Under no circumstances shall the software developers or distributors be held liable for any loss, damage, or other consequences arising from the use of the software or its outputs. Users assume full responsibility for any decisions made based on software use. | D32: This software is provided on “as is” basis, and by using the software you acknowledge and agree that you are doing so at your own risk. While reasonable efforts have been made to ensure the accuracy and reliability of the software, no guarantee is made regarding the correctness, completeness, or suitability of any models, predictions or results it generates. Under no circumstances shall the software developers or distributors be held liable for any loss, damage, or other consequences arising from the use of the software or its outputs. Users assume full responsibility for any decisions made based on software use. | E32: This software is provided on “as is” basis, and by using the software you acknowledge and agree that you are doing so at your own risk. While reasonable efforts have been made to ensure the accuracy and reliability of the software, no guarantee is made regarding the correctness, completeness, or suitability of any models, predictions or results it generates. Under no circumstances shall the software developers or distributors be held liable for any loss, damage, or other consequences arising from the use of the software or its outputs. Users assume full responsibility for any decisions made based on software use. | F32: This software is provided on “as is” basis, and by using the software you acknowledge and agree that you are doing so at your own risk. While reasonable efforts have been made to ensure the accuracy and reliability of the software, no guarantee is made regarding the correctness, completeness, or suitability of any models, predictions or results it generates. Under no circumstances shall the software developers or distributors be held liable for any loss, damage, or other consequences arising from the use of the software or its outputs. Users assume full responsibility for any decisions made based on software use. | G32: This software is provided on “as is” basis, and by using the software you acknowledge and agree that you are doing so at your own risk. While reasonable efforts have been made to ensure the accuracy and reliability of the software, no guarantee is made regarding the correctness, completeness, or suitability of any models, predictions or results it generates. Under no circumstances shall the software developers or distributors be held liable for any loss, damage, or other consequences arising from the use of the software or its outputs. Users assume full responsibility for any decisions made based on software use. | H32: This software is provided on “as is” basis, and by using the software you acknowledge and agree that you are doing so at your own risk. While reasonable efforts have been made to ensure the accuracy and reliability of the software, no guarantee is made regarding the correctness, completeness, or suitability of any models, predictions or results it generates. Under no circumstances shall the software developers or distributors be held liable for any loss, damage, or other consequences arising from the use of the software or its outputs. Users assume full responsibility for any decisions made based on software use.
A33: This software is provided on “as is” basis, and by using the software you acknowledge and agree that you are doing so at your own risk. While reasonable efforts have been made to ensure the accuracy and reliability of the software, no guarantee is made regarding the correctness, completeness, or suitability of any models, predictions or results it generates. Under no circumstances shall the software developers or distributors be held liable for any loss, damage, or other consequences arising from the use of the software or its outputs. Users assume full responsibility for any decisions made based on software use. | B33: This software is provided on “as is” basis, and by using the software you acknowledge and agree that you are doing so at your own risk. While reasonable efforts have been made to ensure the accuracy and reliability of the software, no guarantee is made regarding the correctness, completeness, or suitability of any models, predictions or results it generates. Under no circumstances shall the software developers or distributors be held liable for any loss, damage, or other consequences arising from the use of the software or its outputs. Users assume full responsibility for any decisions made based on software use. | C33: This software is provided on “as is” basis, and by using the software you acknowledge and agree that you are doing so at your own risk. While reasonable efforts have been made to ensure the accuracy and reliability of the software, no guarantee is made regarding the correctness, completeness, or suitability of any models, predictions or results it generates. Under no circumstances shall the software developers or distributors be held liable for any loss, damage, or other consequences arising from the use of the software or its outputs. Users assume full responsibility for any decisions made based on software use. | D33: This software is provided on “as is” basis, and by using the software you acknowledge and agree that you are doing so at your own risk. While reasonable efforts have been made to ensure the accuracy and reliability of the software, no guarantee is made regarding the correctness, completeness, or suitability of any models, predictions or results it generates. Under no circumstances shall the software developers or distributors be held liable for any loss, damage, or other consequences arising from the use of the software or its outputs. Users assume full responsibility for any decisions made based on software use. | E33: This software is provided on “as is” basis, and by using the software you acknowledge and agree that you are doing so at your own risk. While reasonable efforts have been made to ensure the accuracy and reliability of the software, no guarantee is made regarding the correctness, completeness, or suitability of any models, predictions or results it generates. Under no circumstances shall the software developers or distributors be held liable for any loss, damage, or other consequences arising from the use of the software or its outputs. Users assume full responsibility for any decisions made based on software use. | F33: This software is provided on “as is” basis, and by using the software you acknowledge and agree that you are doing so at your own risk. While reasonable efforts have been made to ensure the accuracy and reliability of the software, no guarantee is made regarding the correctness, completeness, or suitability of any models, predictions or results it generates. Under no circumstances shall the software developers or distributors be held liable for any loss, damage, or other consequences arising from the use of the software or its outputs. Users assume full responsibility for any decisions made based on software use. | G33: This software is provided on “as is” basis, and by using the software you acknowledge and agree that you are doing so at your own risk. While reasonable efforts have been made to ensure the accuracy and reliability of the software, no guarantee is made regarding the correctness, completeness, or suitability of any models, predictions or results it generates. Under no circumstances shall the software developers or distributors be held liable for any loss, damage, or other consequences arising from the use of the software or its outputs. Users assume full responsibility for any decisions made based on software use. | H33: This software is provided on “as is” basis, and by using the software you acknowledge and agree that you are doing so at your own risk. While reasonable efforts have been made to ensure the accuracy and reliability of the software, no guarantee is made regarding the correctness, completeness, or suitability of any models, predictions or results it generates. Under no circumstances shall the software developers or distributors be held liable for any loss, damage, or other consequences arising from the use of the software or its outputs. Users assume full responsibility for any decisions made based on software use.
A34: This software is provided on “as is” basis, and by using the software you acknowledge and agree that you are doing so at your own risk. While reasonable efforts have been made to ensure the accuracy and reliability of the software, no guarantee is made regarding the correctness, completeness, or suitability of any models, predictions or results it generates. Under no circumstances shall the software developers or distributors be held liable for any loss, damage, or other consequences arising from the use of the software or its outputs. Users assume full responsibility for any decisions made based on software use. | B34: This software is provided on “as is” basis, and by using the software you acknowledge and agree that you are doing so at your own risk. While reasonable efforts have been made to ensure the accuracy and reliability of the software, no guarantee is made regarding the correctness, completeness, or suitability of any models, predictions or results it generates. Under no circumstances shall the software developers or distributors be held liable for any loss, damage, or other consequences arising from the use of the software or its outputs. Users assume full responsibility for any decisions made based on software use. | C34: This software is provided on “as is” basis, and by using the software you acknowledge and agree that you are doing so at your own risk. While reasonable efforts have been made to ensure the accuracy and reliability of the software, no guarantee is made regarding the correctness, completeness, or suitability of any models, predictions or results it generates. Under no circumstances shall the software developers or distributors be held liable for any loss, damage, or other consequences arising from the use of the software or its outputs. Users assume full responsibility for any decisions made based on software use. | D34: This software is provided on “as is” basis, and by using the software you acknowledge and agree that you are doing so at your own risk. While reasonable efforts have been made to ensure the accuracy and reliability of the software, no guarantee is made regarding the correctness, completeness, or suitability of any models, predictions or results it generates. Under no circumstances shall the software developers or distributors be held liable for any loss, damage, or other consequences arising from the use of the software or its outputs. Users assume full responsibility for any decisions made based on software use. | E34: This software is provided on “as is” basis, and by using the software you acknowledge and agree that you are doing so at your own risk. While reasonable efforts have been made to ensure the accuracy and reliability of the software, no guarantee is made regarding the correctness, completeness, or suitability of any models, predictions or results it generates. Under no circumstances shall the software developers or distributors be held liable for any loss, damage, or other consequences arising from the use of the software or its outputs. Users assume full responsibility for any decisions made based on software use. | F34: This software is provided on “as is” basis, and by using the software you acknowledge and agree that you are doing so at your own risk. While reasonable efforts have been made to ensure the accuracy and reliability of the software, no guarantee is made regarding the correctness, completeness, or suitability of any models, predictions or results it generates. Under no circumstances shall the software developers or distributors be held liable for any loss, damage, or other consequences arising from the use of the software or its outputs. Users assume full responsibility for any decisions made based on software use. | G34: This software is provided on “as is” basis, and by using the software you acknowledge and agree that you are doing so at your own risk. While reasonable efforts have been made to ensure the accuracy and reliability of the software, no guarantee is made regarding the correctness, completeness, or suitability of any models, predictions or results it generates. Under no circumstances shall the software developers or distributors be held liable for any loss, damage, or other consequences arising from the use of the software or its outputs. Users assume full responsibility for any decisions made based on software use. | H34: This software is provided on “as is” basis, and by using the software you acknowledge and agree that you are doing so at your own risk. While reasonable efforts have been made to ensure the accuracy and reliability of the software, no guarantee is made regarding the correctness, completeness, or suitability of any models, predictions or results it generates. Under no circumstances shall the software developers or distributors be held liable for any loss, damage, or other consequences arising from the use of the software or its outputs. Users assume full responsibility for any decisions made based on software use.
A35: This software is provided on “as is” basis, and by using the software you acknowledge and agree that you are doing so at your own risk. While reasonable efforts have been made to ensure the accuracy and reliability of the software, no guarantee is made regarding the correctness, completeness, or suitability of any models, predictions or results it generates. Under no circumstances shall the software developers or distributors be held liable for any loss, damage, or other consequences arising from the use of the software or its outputs. Users assume full responsibility for any decisions made based on software use. | B35: This software is provided on “as is” basis, and by using the software you acknowledge and agree that you are doing so at your own risk. While reasonable efforts have been made to ensure the accuracy and reliability of the software, no guarantee is made regarding the correctness, completeness, or suitability of any models, predictions or results it generates. Under no circumstances shall the software developers or distributors be held liable for any loss, damage, or other consequences arising from the use of the software or its outputs. Users assume full responsibility for any decisions made based on software use. | C35: This software is provided on “as is” basis, and by using the software you acknowledge and agree that you are doing so at your own risk. While reasonable efforts have been made to ensure the accuracy and reliability of the software, no guarantee is made regarding the correctness, completeness, or suitability of any models, predictions or results it generates. Under no circumstances shall the software developers or distributors be held liable for any loss, damage, or other consequences arising from the use of the software or its outputs. Users assume full responsibility for any decisions made based on software use. | D35: This software is provided on “as is” basis, and by using the software you acknowledge and agree that you are doing so at your own risk. While reasonable efforts have been made to ensure the accuracy and reliability of the software, no guarantee is made regarding the correctness, completeness, or suitability of any models, predictions or results it generates. Under no circumstances shall the software developers or distributors be held liable for any loss, damage, or other consequences arising from the use of the software or its outputs. Users assume full responsibility for any decisions made based on software use. | E35: This software is provided on “as is” basis, and by using the software you acknowledge and agree that you are doing so at your own risk. While reasonable efforts have been made to ensure the accuracy and reliability of the software, no guarantee is made regarding the correctness, completeness, or suitability of any models, predictions or results it generates. Under no circumstances shall the software developers or distributors be held liable for any loss, damage, or other consequences arising from the use of the software or its outputs. Users assume full responsibility for any decisions made based on software use. | F35: This software is provided on “as is” basis, and by using the software you acknowledge and agree that you are doing so at your own risk. While reasonable efforts have been made to ensure the accuracy and reliability of the software, no guarantee is made regarding the correctness, completeness, or suitability of any models, predictions or results it generates. Under no circumstances shall the software developers or distributors be held liable for any loss, damage, or other consequences arising from the use of the software or its outputs. Users assume full responsibility for any decisions made based on software use. | G35: This software is provided on “as is” basis, and by using the software you acknowledge and agree that you are doing so at your own risk. While reasonable efforts have been made to ensure the accuracy and reliability of the software, no guarantee is made regarding the correctness, completeness, or suitability of any models, predictions or results it generates. Under no circumstances shall the software developers or distributors be held liable for any loss, damage, or other consequences arising from the use of the software or its outputs. Users assume full responsibility for any decisions made based on software use. | H35: This software is provided on “as is” basis, and by using the software you acknowledge and agree that you are doing so at your own risk. While reasonable efforts have been made to ensure the accuracy and reliability of the software, no guarantee is made regarding the correctness, completeness, or suitability of any models, predictions or results it generates. Under no circumstances shall the software developers or distributors be held liable for any loss, damage, or other consequences arising from the use of the software or its outputs. Users assume full responsibility for any decisions made based on software use.

Sheet Bridge Data
A2: Asset ID | E2: Ownership | O2: Structure | W2: Network | AB2: Asset Attributes | AO2: Funding
A3: Internet Report | B3: Bridge (B/C) | C3: BridgeID (5A01) | D3: BRKey (5A03) | E3: District (5A04) | F3: County (5A05) | G3: Owner Code (5A21) | H3: Submitting Agency (6A06) | I3: Planning Partner (5A13) | J3: City / Town / Place (5A06) | K3: Feature Intersected (5A07) | L3: Facility Carried (5A08) | M3: Location / Structure Name (5A02) | N3: Maintenance Responsibility (5A20) | O3: Structure Length (5B18) | P3: Deck Area (5B19) | Q3: Large Bridge | R3: Span Type | S3: Bridge Family | T3: Struct Type (6A26-29) | U3: Fractural Critical | V3: Parallel Structure (5E02) | W3: Functional Class (5C22) | X3: NHS (5C29) | Y3: NBIS Len (5E01) | Z3: BPN (6A19) | AA3: Interstate | AB3: Deck Surface Type (5B02) | AC3: Wearing Surface Cond (6B40) | AD3: Paint Cond (6B36) | AE3: Paint Ext (6B37) | AF3: Year Built (5A15) | AG3: Age | AH3: ADTT (5C10) | AI3: Risk Score | AJ3: Detour Length (5C15) | AK3: Posting Status (VP02) | AL3: Suff Rating (4A13) | AM3: Leaking Joints | AN3: Scour Critical | AO3: HBRR Elig (6B41) | AP3: P3 (5E24) | AQ3: Federal Aid (6C06) | AR3: Bridge Funding | AX3: Work Done 2026 | AZ3: Work Done 2027 | BB3: Work Done 2028 | BD3: Work Done 2029 | BF3: Work Done 2030 | BH3: Work Done 2031 | BJ3: Work Done 2032 | BL3: Work Done 2033 | BN3: Work Done 2034 | BP3: Work Done 2035 | BR3: Work Done 2036 | BT3: Work Done Y/N | BU3: Work Done > 1 | BV3: Total Work Done > 1 | BW3: Poor On/Off Rate | CI3: 2025 | CU3: 2026 | DO3: 2027 | EI3: 2028 | FC3: 2029 | FW3: 2030 | GQ3: 2031 | HK3: 2032 | IE3: 2033 | IY3: 2034 | JS3: 2035 | KM3: 2036
AR4: NHPP | AS4: STP | AT4: BOF | AU4: BRIP | AV4: State | AW4: N/A | CI4: GCR Deck | CJ4: GCR Sup | CK4: GCR Sub | CL4: GCR Culv | CM4: Deck Dur | CN4: Super Dur | CO4: Sub Dur | CP4: Culv Dur | CQ4: Min GCR | CR4: Poor | CS4: Posted | CU4: GCR Deck | CV4: GCR Sup | CW4: GCR Sub | CX4: GCR Culv | CY4: Deck Dur | CZ4: Super Dur | DA4: Sub Dur | DB4: Culv Dur | DC4: Min GCR | DD4: Poor | DE4: Posted | DF4: Project Pick | DG4: Project Id | DH4: Budget | DI4: Recommended Treatment | DJ4: Cost | DK4: Superseded Treatments | DL4: FHWA Work Types | DM4: Comments | DO4: GCR Deck | DP4: GCR Sup | DQ4: GCR Sub | DR4: GCR Culv | DS4: Deck Dur | DT4: Super Dur | DU4: Sub Dur | DV4: Culv Dur | DW4: Min GCR | DX4: Poor | DY4: Posted | DZ4: Project Pick | EA4: Project Id | EB4: Budget | EC4: Recommended Treatment | ED4: Cost | EE4: Superseded Treatments | EF4: FHWA Work Types | EG4: Comments | EI4: GCR Deck | EJ4: GCR Sup | EK4: GCR Sub | EL4: GCR Culv | EM4: Deck Dur | EN4: Super Dur | EO4: Sub Dur | EP4: Culv Dur | EQ4: Min GCR | ER4: Poor | ES4: Posted | ET4: Project Pick | EU4: Project Id | EV4: Budget | EW4: Recommended Treatment | EX4: Cost | EY4: Superseded Treatments | EZ4: FHWA Work Types | FA4: Comments | FC4: GCR Deck | FD4: GCR Sup | FE4: GCR Sub | FF4: GCR Culv | FG4: Deck Dur | FH4: Super Dur | FI4: Sub Dur | FJ4: Culv Dur | FK4: Min GCR | FL4: Poor | FM4: Posted | FN4: Project Pick | FO4: Project Id | FP4: Budget | FQ4: Recommended Treatment | FR4: Cost | FS4: Superseded Treatments | FT4: FHWA Work Types | FU4: Comments | FW4: GCR Deck | FX4: GCR Sup | FY4: GCR Sub | FZ4: GCR Culv | GA4: Deck Dur | GB4: Super Dur | GC4: Sub Dur | GD4: Culv Dur | GE4: Min GCR | GF4: Poor | GG4: Posted | GH4: Project Pick | GI4: Project Id | GJ4: Budget | GK4: Recommended Treatment | GL4: Cost | GM4: Superseded Treatments | GN4: FHWA Work Types | GO4: Comments | GQ4: GCR Deck | GR4: GCR Sup | GS4: GCR Sub | GT4: GCR Culv | GU4: Deck Dur | GV4: Super Dur | GW4: Sub Dur | GX4: Culv Dur | GY4: Min GCR | GZ4: Poor | HA4: Posted | HB4: Project Pick | HC4: Project Id | HD4: Budget | HE4: Recommended Treatment | HF4: Cost | HG4: Superseded Treatments | HH4: FHWA Work Types | HI4: Comments | HK4: GCR Deck | HL4: GCR Sup | HM4: GCR Sub | HN4: GCR Culv | HO4: Deck Dur | HP4: Super Dur | HQ4: Sub Dur | HR4: Culv Dur | HS4: Min GCR | HT4: Poor | HU4: Posted | HV4: Project Pick | HW4: Project Id | HX4: Budget | HY4: Recommended Treatment | HZ4: Cost | IA4: Superseded Treatments | IB4: FHWA Work Types | IC4: Comments | IE4: GCR Deck | IF4: GCR Sup | IG4: GCR Sub | IH4: GCR Culv | II4: Deck Dur | IJ4: Super Dur | IK4: Sub Dur | IL4: Culv Dur | IM4: Min GCR | IN4: Poor | IO4: Posted | IP4: Project Pick | IQ4: Project Id | IR4: Budget | IS4: Recommended Treatment | IT4: Cost | IU4: Superseded Treatments | IV4: FHWA Work Types | IW4: Comments | IY4: GCR Deck | IZ4: GCR Sup | JA4: GCR Sub | JB4: GCR Culv | JC4: Deck Dur | JD4: Super Dur | JE4: Sub Dur | JF4: Culv Dur | JG4: Min GCR | JH4: Poor | JI4: Posted | JJ4: Project Pick | JK4: Project Id | JL4: Budget | JM4: Recommended Treatment | JN4: Cost | JO4: Superseded Treatments | JP4: FHWA Work Types | JQ4: Comments | JS4: GCR Deck | JT4: GCR Sup | JU4: GCR Sub | JV4: GCR Culv | JW4: Deck Dur | JX4: Super Dur | JY4: Sub Dur | JZ4: Culv Dur | KA4: Min GCR | KB4: Poor | KC4: Posted | KD4: Project Pick | KE4: Project Id | KF4: Budget | KG4: Recommended Treatment | KH4: Cost | KI4: Superseded Treatments | KJ4: FHWA Work Types | KK4: Comments | KM4: GCR Deck | KN4: GCR Sup | KO4: GCR Sub | KP4: GCR Culv | KQ4: Deck Dur | KR4: Super Dur | KS4: Sub Dur | KT4: Culv Dur | KU4: Min GCR | KV4: Poor | KW4: Posted | KX4: Project Pick | KY4: Project Id | KZ4: Budget | LA4: Recommended Treatment | LB4: Cost | LC4: Superseded Treatments | LD4: FHWA Work Types | LE4: Comments
AX5: Work | AY5: Cost | AZ5: Work | BA5: Cost | BB5: Work | BC5: Cost | BD5: Work | BE5: Cost | BF5: Work | BG5: Cost | BH5: Work | BI5: Cost | BJ5: Work | BK5: Cost | BL5: Work | BM5: Cost | BN5: Work | BO5: Cost | BP5: Work | BQ5: Cost | BR5: Work | BS5: Cost | BV5: 2 | BW5: 2026 | BX5: 2027 | BY5: 2028 | BZ5: 2029 | CA5: 2030 | CB5: 2031 | CC5: 2032 | CD5: 2033 | CE5: 2034 | CF5: 2035 | CG5: 2036
A6: Local | B6: B | C6: 51720104100102 | D6: 30015 | E6: 04 | F6: Pike | G6: 02 - County Highway Agency | H6: 051 | I6: NEPA RPO | K6: SHOHOLA CREEK | L6: SPRING ROAD | M6: PIERSON BRIDGE, PIKE COUNTY BRIDGE #2 | N6: County Highway Agency | O6: 21 | P6: 342.3 | Q6: N | R6: Single | S6: 2 | T6: Steel, I beams | U6: N | V6: N | W6: 09 - Rural - Local | X6: N | Y6: Y | Z6: L | AA6: N | AB6: 06 - Bituminous (applies only to structures with no deck) | AC6: 8 | AD6: 3 | AE6: 4 | AF6: 1924 | AG6: 103 | AH6: 10 | AI6: 117 | AJ6: 99 | AK6: POSTED | AL6: 43 | AM6: N | AN6: D | AO6: P | AP6: N | AQ6: 0 - Not on Federal Route | AR6: N | AS6: N | AT6: Y | AU6: N | AV6: Y | AW6: N | AX6: culvert replacement (box frame | AY6: 900000 | AZ6: -- | BA6: 0 | BB6: -- | BC6: 0 | BD6: -- | BE6: 0 | BF6: -- | BG6: 0 | BH6: -- | BI6: 0 | BJ6: -- | BK6: 0 | BL6: -- | BM6: 0 | BN6: -- | BO6: 0 | BP6: -- | BQ6: 0 | BR6: -- | BS6: 0 | BT6: Yes | BU6: -- | BW6: Off | BX6: -- | BY6: -- | BZ6: -- | CA6: -- | CB6: -- | CC6: -- | CD6: -- | CE6: -- | CF6: -- | CG6: -- | CI6: 4.724 | CJ6: 5.827 | CK6: 4.448 | CL6: N | CM6: 4 | CN6: 4 | CO6: 12 | CP6: N | CQ6: 4.448 | CR6: Y | CS6: Y | CU6: 9.99 | CV6: 9.99 | CW6: 9.99 | CX6: N | CY6: 1 | CZ6: 1 | DA6: 1 | DB6: N | DC6: 9.99 | DD6: N | DE6: Y | DF6: BAMS Pick | DH6: NEPA_581 | DI6: Culvert Replacement (Box Frame | DJ6: 900000 | DL6: Replacement | DO6: 9.847 | DP6: 9.879 | DQ6: 9.79 | DR6: N | DS6: 2 | DT6: 2 | DU6: 2 | DV6: N | DW6: 9.79 | DX6: N | DY6: Y | DZ6: BAMS Pick | EC6: No Treatment | ED6: 0 | EF6: Maintenance | EI6: 9.704 | EJ6: 9.768 | EK6: 9.59 | EL6: N | EM6: 3 | EN6: 3 | EO6: 3 | EP6: N | EQ6: 9.59 | ER6: N | ES6: Y | ET6: BAMS Pick | EW6: No Treatment | EX6: 0 | EZ6: Maintenance | FC6: 9.561 | FD6: 9.657 | FE6: 9.39 | FF6: N | FG6: 4 | FH6: 4 | FI6: 4 | FJ6: N | FK6: 9.39 | FL6: N | FM6: Y | FN6: BAMS Pick | FQ6: No Treatment | FR6: 0 | FT6: Maintenance | FW6: 9.418 | FX6: 9.546 | FY6: 9.19 | FZ6: N | GA6: 5 | GB6: 5 | GC6: 5 | GD6: N | GE6: 9.19 | GF6: N | GG6: Y | GH6: BAMS Pick | GK6: No Treatment | GL6: 0 | GN6: Maintenance | GQ6: 9.275 | GR6: 9.435 | GS6: 8.99285 | GT6: N | GU6: 6 | GV6: 6 | GW6: 1 | GX6: N | GY6: 8.99285 | GZ6: N | HA6: Y | HB6: BAMS Pick | HE6: No Treatment | HF6: 0 | HH6: Maintenance | HK6: 9.132 | HL6: 9.324 | HM6: 8.84985 | HN6: N | HO6: 7 | HP6: 7 | HQ6: 2 | HR6: N | HS6: 8.84985 | HT6: N | HU6: Y | HV6: BAMS Pick | HY6: No Treatment | HZ6: 0 | IB6: Maintenance | IE6: 8.9912378 | IF6: 9.213 | IG6: 8.70685 | IH6: N | II6: 1 | IJ6: 8 | IK6: 3 | IL6: N | IM6: 8.70685 | IN6: N | IO6: Y | IP6: BAMS Pick | IS6: No Treatment | IT6: 0 | IV6: Maintenance | IY6: 8.8802378 | IZ6: 9.102 | JA6: 8.56385 | JB6: N | JC6: 2 | JD6: 9 | JE6: 4 | JF6: N | JG6: 8.56385 | JH6: N | JI6: Y | JJ6: BAMS Pick | JM6: No Treatment | JN6: 0 | JP6: Maintenance | JS6: 8.7692378 | JT6: 8.9946036 | JU6: 8.42085 | JV6: N | JW6: 3 | JX6: 1 | JY6: 5 | JZ6: N | KA6: 8.42085 | KB6: N | KC6: Y | KD6: BAMS Pick | KG6: No Treatment | KH6: 0 | KJ6: Maintenance | KM6: 8.6582378 | KN6: 8.9236036 | KO6: 8.27785 | KP6: N | KQ6: 4 | KR6: 2 | KS6: 6 | KT6: N | KU6: 8.27785 | KV6: N | KW6: Y | KX6: BAMS Pick | LA6: No Treatment | LB6: 0 | LD6: Maintenance
